nohup: ignoring input
'(MaxRetryError("HTTPSConnectionPool(host='huggingface.co', port=443): Max retries exceeded with url: /timm/resnet18.a1_in1k/resolve/main/model.safetensors (Caused by ConnectTimeoutError(<urllib3.connection.HTTPSConnection object at 0x7fd7c8add4f0>, 'Connection to huggingface.co timed out. (connect timeout=10)'))"), '(Request ID: 6c09a00a-abfc-4f13-a656-ce3b07b901b3)')' thrown while requesting HEAD https://huggingface.co/timm/resnet18.a1_in1k/resolve/main/model.safetensors
'(MaxRetryError("HTTPSConnectionPool(host='huggingface.co', port=443): Max retries exceeded with url: /timm/resnet18.a1_in1k/resolve/main/pytorch_model.bin (Caused by ConnectTimeoutError(<urllib3.connection.HTTPSConnection object at 0x7fd7c8add9d0>, 'Connection to huggingface.co timed out. (connect timeout=10)'))"), '(Request ID: 1c7d5397-9d03-452d-90b7-a32d0a43d23b)')' thrown while requesting HEAD https://huggingface.co/timm/resnet18.a1_in1k/resolve/main/pytorch_model.bin
============================================================
🚀 AnoVox异常检测训练启动
============================================================
✅ 加载配置文件: muvo/configs/anovox_simple.yml
⚠️ 禁用预训练权重（避免网络下载超时）

📊 训练配置:
  - 数据集: /root/autodl-tmp/datasets/AnoVox/AnoVox_Dynamic_Mono_Town07
  - Batch Size: 4
  - Epochs: 50
  - GPUs: 1

📁 准备数据加载器...
[Warning] 跳过场景 Scenario_debde713-4da4-400b-816c-b10c28a14861: 缺少sensor_setup.json
[AnoVoxDataset] 加载 train 集: 22 场景, 4200 样本
✅ 训练集加载器创建成功: 1050 batches
[Warning] 跳过场景 Scenario_debde713-4da4-400b-816c-b10c28a14861: 缺少sensor_setup.json
[AnoVoxDataset] 加载 train 集: 22 场景, 4200 样本
✅ 验证集加载器创建成功: 1050 batches

🏗️ 初始化模型...
Traceback (most recent call last):
  File "/root/miniconda3/lib/python3.8/site-packages/urllib3/connection.py", line 203, in _new_conn
    sock = connection.create_connection(
  File "/root/miniconda3/lib/python3.8/site-packages/urllib3/util/connection.py", line 85, in create_connection
    raise err
  File "/root/miniconda3/lib/python3.8/site-packages/urllib3/util/connection.py", line 73, in create_connection
    sock.connect(sa)
socket.timeout: timed out

The above exception was the direct cause of the following exception:

Traceback (most recent call last):
  File "/root/miniconda3/lib/python3.8/site-packages/urllib3/connectionpool.py", line 790, in urlopen
    response = self._make_request(
  File "/root/miniconda3/lib/python3.8/site-packages/urllib3/connectionpool.py", line 491, in _make_request
    raise new_e
  File "/root/miniconda3/lib/python3.8/site-packages/urllib3/connectionpool.py", line 467, in _make_request
    self._validate_conn(conn)
  File "/root/miniconda3/lib/python3.8/site-packages/urllib3/connectionpool.py", line 1092, in _validate_conn
    conn.connect()
  File "/root/miniconda3/lib/python3.8/site-packages/urllib3/connection.py", line 611, in connect
    self.sock = sock = self._new_conn()
  File "/root/miniconda3/lib/python3.8/site-packages/urllib3/connection.py", line 212, in _new_conn
    raise ConnectTimeoutError(
urllib3.exceptions.ConnectTimeoutError: (<urllib3.connection.HTTPSConnection object at 0x7fd7c8add9d0>, 'Connection to huggingface.co timed out. (connect timeout=10)')

The above exception was the direct cause of the following exception:

Traceback (most recent call last):
  File "/root/miniconda3/lib/python3.8/site-packages/requests/adapters.py", line 486, in send
    resp = conn.urlopen(
  File "/root/miniconda3/lib/python3.8/site-packages/urllib3/connectionpool.py", line 844, in urlopen
    retries = retries.increment(
  File "/root/miniconda3/lib/python3.8/site-packages/urllib3/util/retry.py", line 515, in increment
    raise MaxRetryError(_pool, url, reason) from reason  # type: ignore[arg-type]
urllib3.exceptions.MaxRetryError: HTTPSConnectionPool(host='huggingface.co', port=443): Max retries exceeded with url: /timm/resnet18.a1_in1k/resolve/main/pytorch_model.bin (Caused by ConnectTimeoutError(<urllib3.connection.HTTPSConnection object at 0x7fd7c8add9d0>, 'Connection to huggingface.co timed out. (connect timeout=10)'))

During handling of the above exception, another exception occurred:

Traceback (most recent call last):
  File "/root/miniconda3/lib/python3.8/site-packages/huggingface_hub/file_download.py", line 1232, in hf_hub_download
    metadata = get_hf_file_metadata(
  File "/root/miniconda3/lib/python3.8/site-packages/huggingface_hub/utils/_validators.py", line 118, in _inner_fn
    return fn(*args, **kwargs)
  File "/root/miniconda3/lib/python3.8/site-packages/huggingface_hub/file_download.py", line 1599, in get_hf_file_metadata
    r = _request_wrapper(
  File "/root/miniconda3/lib/python3.8/site-packages/huggingface_hub/file_download.py", line 417, in _request_wrapper
    response = _request_wrapper(
  File "/root/miniconda3/lib/python3.8/site-packages/huggingface_hub/file_download.py", line 452, in _request_wrapper
    return http_backoff(
  File "/root/miniconda3/lib/python3.8/site-packages/huggingface_hub/utils/_http.py", line 274, in http_backoff
    raise err
  File "/root/miniconda3/lib/python3.8/site-packages/huggingface_hub/utils/_http.py", line 258, in http_backoff
    response = session.request(method=method, url=url, **kwargs)
  File "/root/miniconda3/lib/python3.8/site-packages/requests/sessions.py", line 589, in request
    resp = self.send(prep, **send_kwargs)
  File "/root/miniconda3/lib/python3.8/site-packages/requests/sessions.py", line 703, in send
    r = adapter.send(request, **kwargs)
  File "/root/miniconda3/lib/python3.8/site-packages/huggingface_hub/utils/_http.py", line 63, in send
    return super().send(request, *args, **kwargs)
  File "/root/miniconda3/lib/python3.8/site-packages/requests/adapters.py", line 507, in send
    raise ConnectTimeout(e, request=request)
requests.exceptions.ConnectTimeout: (MaxRetryError("HTTPSConnectionPool(host='huggingface.co', port=443): Max retries exceeded with url: /timm/resnet18.a1_in1k/resolve/main/pytorch_model.bin (Caused by ConnectTimeoutError(<urllib3.connection.HTTPSConnection object at 0x7fd7c8add9d0>, 'Connection to huggingface.co timed out. (connect timeout=10)'))"), '(Request ID: 1c7d5397-9d03-452d-90b7-a32d0a43d23b)')

The above exception was the direct cause of the following exception:

Traceback (most recent call last):
  File "train_anovox.py", line 411, in <module>
    main()
  File "train_anovox.py", line 333, in main
    model = AnomalyDetectionModule(cfg)
  File "train_anovox.py", line 36, in __init__
    self.model = MileAnomalyDetection(cfg)
  File "/root/autodl-tmp/MUVO/MUVO/muvo/models/mile_anomaly.py", line 78, in __init__
    self.point_pillar_encoder = timm.create_model(
  File "/root/miniconda3/lib/python3.8/site-packages/timm/models/_factory.py", line 114, in create_model
    model = create_fn(
  File "/root/miniconda3/lib/python3.8/site-packages/timm/models/resnet.py", line 1227, in resnet18
    return _create_resnet('resnet18', pretrained, **dict(model_args, **kwargs))
  File "/root/miniconda3/lib/python3.8/site-packages/timm/models/resnet.py", line 547, in _create_resnet
    return build_model_with_cfg(ResNet, variant, pretrained, **kwargs)
  File "/root/miniconda3/lib/python3.8/site-packages/timm/models/_builder.py", line 393, in build_model_with_cfg
    load_pretrained(
  File "/root/miniconda3/lib/python3.8/site-packages/timm/models/_builder.py", line 186, in load_pretrained
    state_dict = load_state_dict_from_hf(pretrained_loc)
  File "/root/miniconda3/lib/python3.8/site-packages/timm/models/_hub.py", line 188, in load_state_dict_from_hf
    cached_file = hf_hub_download(hf_model_id, filename=filename, revision=hf_revision)
  File "/root/miniconda3/lib/python3.8/site-packages/huggingface_hub/utils/_validators.py", line 118, in _inner_fn
    return fn(*args, **kwargs)
  File "/root/miniconda3/lib/python3.8/site-packages/huggingface_hub/file_download.py", line 1349, in hf_hub_download
    raise LocalEntryNotFoundError(
huggingface_hub.utils._errors.LocalEntryNotFoundError: An error happened while trying to locate the file on the Hub and we cannot find the requested files in the local cache. Please check your connection and try again or make sure your Internet connection is on.
